Workbook

Sheet Contadores_Ofic
A1: Region | B1: Nombre Oficina | C1: Codigo de Oficina | D1: Nombre de Host Oficina | E1: DisplayName | F1: Serial | G1: IPv4Address | H1: Contador Mes Anterior | I1: Contador Semana 1 | J1: Contador Final Semana 1 | K1: Contador Semana 2 | L1: Contador Final Semana 2 | M1: Contador Semana 3 | N1: Contador Final Semana 3 | O1: Contador Semana 4 | P1: Contador Final Semana 4 | Q1: Contador Semana 5 | R1: Contador Final Semana 5 | S1: Contador Mensual | T1: Fecha | U1: Observaciones | V1: Status impresora | W1: Estatus Agencia
A2: Metro I | B2: I.E.S.A | C2: 9948 | D2: 9948MFAP01 | E2: Canon iR1025 | F2: DRL37783 | G2: 10.10.13.200 | H2: 46532 | I2: 46573 | J2: =I2-H2 -> 41 | K2: =VLOOKUP(G2,'[1]01-09 al 30-09'!$G:$AA,21,FALSE) -> 46608 | L2: =K2-I2 -> 35 | M2: =VLOOKUP(G2,'[1]01-09 al 30-09'!$G:$AI,29,FALSE) -> 46628 | N2: =M2-K2 -> 20 | O2: =VLOOKUP(G2,'[1]01-09 al 30-09'!$G:$AS,39,FALSE) -> 46668 | P2: =O2-M2 -> 40 | S2: =R2+P2+N2+L2+J2 -> 136 | T2: 46146 | V2: Instalado | W2: =VLOOKUP(C2,'Status oficina'!$A$2:$C$208,3,FALSE) -> Activa
A3: Oriente | B3: Maturin La Cascada | C3: 9503 | D3: 9503MFTQ01 | E3: Canon iR1025 | F3: DRL37786 | G3: 10.10.1.200 | H3: 55906 | I3: 55955 | J3: =I3-H3 -> 49 | K3: 55980 | L3: =K3-I3 -> 25 | M3: =VLOOKUP(G3,'[1]01-09 al 30-09'!$G:$AI,29,FALSE) -> 56025 | N3: =M3-K3 -> 45 | O3: =VLOOKUP(G3,'[1]01-09 al 30-09'!$G:$AS,39,FALSE) -> 56054 | P3: =O3-M3 -> 29 | S3: =R3+P3+N3+L3+J3 -> 148 | T3: 46146 | V3: Instalado | W3: =VLOOKUP(C3,'Status oficina'!$A$2:$C$208,3,FALSE) -> Activa
A4: Occidente | B4: Las Tapias | C4: 9892 | D4: 9892MFTQ01 | E4: Canon iR1025 | F4: DRL37787 | G4: 10.14.7.200 | H4: 146483 | I4: 146584 | J4: =I4-H4 -> 101 | K4: 146867 | L4: =K4-I4 -> 283 | M4: =VLOOKUP(G4,'[1]01-09 al 30-09'!$G:$AI,29,FALSE) -> 146967 | N4: =M4-K4 -> 100 | O4: =VLOOKUP(G4,'[1]01-09 al 30-09'!$G:$AS,39,FALSE) -> 147175 | P4: =O4-M4 -> 208 | S4: =R4+P4+N4+L4+J4 -> 692 | T4: 46146 | V4: Instalado | W4: =VLOOKUP(C4,'Status oficina'!$A$2:$C$208,3,FALSE) -> Activa
A5: Metro I | B5: San Francisco (H) | C5: 9211 | D5: 9211MFGE01 | E5: Canon iR1025 | F5: DRL51898 | G5: 10.11.29.205 | H5: 172355 | I5: 172355 | J5: =I5-H5 -> 0 | K5: 172355 | L5: =K5-I5 -> 0 | M5: =VLOOKUP(G5,'[1]01-09 al 30-09'!$G:$AI,29,FALSE) -> 172355 | N5: =M5-K5 -> 0 | O5: =VLOOKUP(G5,'[1]01-09 al 30-09'!$G:$AS,39,FALSE) -> 172355 | P5: =O5-M5 -> 0 | S5: =R5+P5+N5+L5+J5 -> 0 | T5: 46146 | U5: No se embalo solo para scanear | V5: Pendiente Retiro | W5: =VLOOKUP(C5,'Status oficina'!$A$2:$C$208,3,FALSE) -> Activa
A6: Metro I | B6: Av. Francisco Solano | C6: 9214 | D6: 9214MFCO01 | E6: Canon iR1025 | F6: DRL37936 | G6: 10.10.6.202 | H6: 152288 | I6: 152288 | J6: =I6-H6 -> 0 | K6: 152288 | L6: =K6-I6 -> 0 | M6: =VLOOKUP(G6,'[1]01-09 al 30-09'!$G:$AI,29,FALSE) -> 152288 | N6: =M6-K6 -> 0 | O6: =VLOOKUP(G6,'[1]01-09 al 30-09'!$G:$AS,39,FALSE) -> 152288 | P6: =O6-M6 -> 0 | S6: =R6+P6+N6+L6+J6 -> 0 | T6: 46146 | V6: Cierre temporal | W6: Cierre temporal
A7: Metro I | B7: San Francisco (H) | C7: 9211 | D7: 9211MFEN01 | E7: Canon iR2525 | F7: FRU46126 | G7: 10.11.29.204 | H7: 448206 | I7: 448206 | J7: =I7-H7 -> 0 | K7: 448206 | L7: =K7-I7 -> 0 | M7: =VLOOKUP(G7,'[1]01-09 al 30-09'!$G:$AI,29,FALSE) -> 448206 | N7: =M7-K7 -> 0 | O7: =VLOOKUP(G7,'[1]01-09 al 30-09'!$G:$AS,39,FALSE) -> 448206 | P7: =O7-M7 -> 0 | S7: =R7+P7+N7+L7+J7 -> 0 | T7: 46146 | U7: Equipo embalado pendiente retiro | V7: Pendiente Retiro | W7: =VLOOKUP(C7,'Status oficina'!$A$2:$C$208,3,FALSE) -> Activa
A8: Oriente | B8: Las Garzas | C8: 9655 | D8: 9655MFGE03 | E8: Canon iR1025 | F8: DRL37941 | G8: 10.10.206.206 | H8: 119620 | I8: 119818 | J8: =I8-H8 -> 198 | K8: 119915 | L8: =K8-I8 -> 97 | M8: =VLOOKUP(G8,'[1]01-09 al 30-09'!$G:$AI,29,FALSE) -> 119985 | N8: =M8-K8 -> 70 | O8: =VLOOKUP(G8,'[1]01-09 al 30-09'!$G:$AS,39,FALSE) -> 120042 | P8: =O8-M8 -> 57 | S8: =R8+P8+N8+L8+J8 -> 422 | T8: 46146 | U8: Se encuentra ubicada Piso 1 gerente de operaciones | V8: Instalado | W8: =VLOOKUP(C8,'Status oficina'!$A$2:$C$208,3,FALSE) -> Activa
A9: Metro I | B9: Hosp. Clinicas Caracas | C9: 9935 | D9: 9935MFAP01 | E9: Canon iR1025 | F9: DRL37947 | G9: 10.11.98.200 | H9: 340906 | I9: 341234 | J9: =I9-H9 -> 328 | K9: 341406 | L9: =K9-I9 -> 172 | M9: =VLOOKUP(G9,'[1]01-09 al 30-09'!$G:$AI,29,FALSE) -> 341688 | N9: =M9-K9 -> 282 | O9: =VLOOKUP(G9,'[1]01-09 al 30-09'!$G:$AS,39,FALSE) -> 342026 | P9: =O9-M9 -> 338 | S9: =R9+P9+N9+L9+J9 -> 1120 | T9: 46146 | V9: Instalado | W9: =VLOOKUP(C9,'Status oficina'!$A$2:$C$208,3,FALSE) -> Activa
A10: Centro Occidental | B10: Guanare | C10: 9832 | D10: 9832MFGE01 | E10: Canon iR1025 | F10: DRL37949 | G10: 10.10.60.200 | H10: 133262 | I10: 133262 | J10: =I10-H10 -> 0 | K10: 133650 | L10: =K10-I10 -> 388 | M10: =VLOOKUP(G10,'[1]01-09 al 30-09'!$G:$AI,29,FALSE) -> 133740 | N10: =M10-K10 -> 90 | O10: =VLOOKUP(G10,'[1]01-09 al 30-09'!$G:$AS,39,FALSE) -> 134387 | P10: =O10-M10 -> 647 | S10: =R10+P10+N10+L10+J10 -> 1125 | T10: 46146 | U10: Activa sin impresiones | V10: Instalado | W10: =VLOOKUP(C10,'Status oficina'!$A$2:$C$208,3,FALSE) -> Activa
A11: Occidente | B11: Mérida | C11: 9822 | D11: 9822MFGE01 | E11: Canon iR1025 | F11: DRL37951 | G11: 10.10.80.201 | H11: 474521 | I11: 474746 | J11: =I11-H11 -> 225 | K11: 474846 | L11: =K11-I11 -> 100 | M11: =VLOOKUP(G11,'[1]01-09 al 30-09'!$G:$AI,29,FALSE) -> 474961 | N11: =M11-K11 -> 115 | O11: =VLOOKUP(G11,'[1]01-09 al 30-09'!$G:$AS,39,FALSE) -> 475097 | P11: =O11-M11 -> 136 | S11: =R11+P11+N11+L11+J11 -> 576 | T11: 46146 | V11: Instalado | W11: =VLOOKUP(C11,'Status oficina'!$A$2:$C$208,3,FALSE) -> Activa
A12: Metro I | B12: Santa Mónica | C12: 9232 | D12: 9232MFTQ01 | E12: Canon iR1025 | F12: DRL37952 | G12: 10.10.125.203 | H12: 179094 | I12: 179194 | J12: =I12-H12 -> 100 | K12: 179281 | L12: =K12-I12 -> 87 | M12: =VLOOKUP(G12,'[1]01-09 al 30-09'!$G:$AI,29,FALSE) -> 179349 | N12: =M12-K12 -> 68 | O12: =VLOOKUP(G12,'[1]01-09 al 30-09'!$G:$AS,39,FALSE) -> 179374 | P12: =O12-M12 -> 25 | S12: =R12+P12+N12+L12+J12 -> 280 | T12: 46146 | V12: Instalado | W12: =VLOOKUP(C12,'Status oficina'!$A$2:$C$208,3,FALSE) -> Activa
A13: Metro I | B13: San Francisco (H) | C13: 9211 | D13: 9211MFTQ01 | E13: Canon iR1025 | F13: DRL37991 | G13: 10.11.29.202 | H13: 133847 | I13: 133939 | J13: =I13-H13 -> 92 | K13: 134029 | L13: =K13-I13 -> 90 | M13: =VLOOKUP(G13,'[1]01-09 al 30-09'!$G:$AI,29,FALSE) -> 134078 | N13: =M13-K13 -> 49 | O13: =VLOOKUP(G13,'[1]01-09 al 30-09'!$G:$AS,39,FALSE) -> 134224 | P13: =O13-M13 -> 146 | S13: =R13+P13+N13+L13+J13 -> 377 | T13: 46146 | V13: Instalado | W13: =VLOOKUP(C13,'Status oficina'!$A$2:$C$208,3,FALSE) -> Activa
A14: Metro II | B14: El Rosal | C14: 9224 | D14: 9224MFTQ01 | E14: Canon iR1025 | F14: DRL38000 | G14: 10.10.180.204 | H14: 154740 | I14: 154816 | J14: =I14-H14 -> 76 | K14: 154958 | L14: =K14-I14 -> 142 | M14: =VLOOKUP(G14,'[1]01-09 al 30-09'!$G:$AI,29,FALSE) -> 155094 | N14: =M14-K14 -> 136 | O14: =VLOOKUP(G14,'[1]01-09 al 30-09'!$G:$AS,39,FALSE) -> 155189 | P14: =O14-M14 -> 95 | S14: =R14+P14+N14+L14+J14 -> 449 | T14: 46146 | V14: Instalado | W14: =VLOOKUP(C14,'Status oficina'!$A$2:$C$208,3,FALSE) -> Activa
A15: Metro II | B15: El Rosal | C15: 9224 | D15: 9224MFAP01 | E15: Canon iR1025 | F15: DRL38005 | G15: 10.10.180.203 | H15: 314764 | I15: 315696 | J15: =I15-H15 -> 932 | K15: 316647 | L15: =K15-I15 -> 951 | M15: =VLOOKUP(G15,'[1]01-09 al 30-09'!$G:$AI,29,FALSE) -> 317569 | N15: =M15-K15 -> 922 | O15: =VLOOKUP(G15,'[1]01-09 al 30-09'!$G:$AS,39,FALSE) -> 318415 | P15: =O15-M15 -> 846 | S15: =R15+P15+N15+L15+J15 -> 3651 | T15: 46146 | V15: Instalado | W15: =VLOOKUP(C15,'Status oficina'!$A$2:$C$208,3,FALSE) -> Activa
A16: Metro I | B16: Casa Bera | C16: 9203 | D16: 9203MFGE01 | E16: Canon iR1025 | F16: DRL38009 | G16: 10.14.72.200 | H16: 306785 | I16: 306785 | J16: =I16-H16 -> 0 | K16: 306785 | L16: =K16-I16 -> 0 | M16: =VLOOKUP(G16,'[1]01-09 al 30-09'!$G:$AI,29,FALSE) -> 306785 | N16: =M16-K16 -> 0 | O16: =VLOOKUP(G16,'[1]01-09 al 30-09'!$G:$AS,39,FALSE) -> 306785 | P16: =O16-M16 -> 0 | S16: =R16+P16+N16+L16+J16 -> 0 | T16: 46146 | U16: Se embala impresora por no tener uso 25/02/2025/Cierre Definitivo 04/12/2025 | V16: Cierre definitivo | W16: Cierre definitivo
A17: Occidente | B17: Barrio Obrero | C17: 9963 | D17: 9963MFTQ01 | E17: Canon iR1025 | F17: DRL39190 | G17: 10.11.99.201 | H17: 127579 | I17: 127875 | J17: =I17-H17 -> 296 | K17: 128229 | L17: =K17-I17 -> 354 | M17: =VLOOKUP(G17,'[1]01-09 al 30-09'!$G:$AI,29,FALSE) -> 128401 | N17: =M17-K17 -> 172 | O17: =VLOOKUP(G17,'[1]01-09 al 30-09'!$G:$AS,39,FALSE) -> 128650 | P17: =O17-M17 -> 249 | S17: =R17+P17+N17+L17+J17 -> 1071 | T17: 46146 | V17: Instalado | W17: =VLOOKUP(C17,'Status oficina'!$A$2:$C$208,3,FALSE) -> Activa
A18: Occidente | B18: La Concordia | C18: 9837 | D18: 9837MFTQ01 | E18: Canon iR1025 | F18: DRL39193 | G18: 10.14.11.204 | H18: 246164 | I18: 246795 | J18: =I18-H18 -> 631 | K18: 247354 | L18: =K18-I18 -> 559 | M18: =VLOOKUP(G18,'[1]01-09 al 30-09'!$G:$AI,29,FALSE) -> 247859 | N18: =M18-K18 -> 505 | O18: =VLOOKUP(G18,'[1]01-09 al 30-09'!$G:$AS,39,FALSE) -> 248344 | P18: =O18-M18 -> 485 | S18: =R18+P18+N18+L18+J18 -> 2180 | T18: 46146 | V18: Instalado | W18: =VLOOKUP(C18,'Status oficina'!$A$2:$C$208,3,FALSE) -> Activa
A19: Occidente | B19: San Cristobal II | C19: 9895 | D19: 9895MFTQ01 | E19: Canon iR1025 | F19: DRL39198 | G19: 10.14.12.201 | H19: 93852 | I19: 93852 | J19: =I19-H19 -> 0 | K19: 93852 | L19: =K19-I19 -> 0 | M19: =VLOOKUP(G19,'[1]01-09 al 30-09'!$G:$AI,29,FALSE) -> 93852 | N19: =M19-K19 -> 0 | O19: =VLOOKUP(G19,'[1]01-09 al 30-09'!$G:$AS,39,FALSE) -> 93852 | P19: =O19-M19 -> 0 | S19: =R19+P19+N19+L19+J19 -> 0 | T19: 46146 | U19: Sin Linea desde el 14 al 22/10 | V19: Cierre definitivo | W19: =VLOOKUP(C19,'Status oficina'!$A$2:$C$208,3,FALSE) -> Cierre definitivo
A20: Centro Occidental | B20: Plaza Bolivar | C20: 9410 | D20: 9410MFCO01 | E20: Canon iR1025 | F20: DRL39401 | G20: 10.11.25.200 | H20: 144237 | I20: 144409 | J20: =I20-H20 -> 172 | K20: 144724 | L20: =K20-I20 -> 315 | M20: =VLOOKUP(G20,'[1]01-09 al 30-09'!$G:$AI,29,FALSE) -> 144788 | N20: =M20-K20 -> 64 | O20: =VLOOKUP(G20,'[1]01-09 al 30-09'!$G:$AS,39,FALSE) -> 145081 | P20: =O20-M20 -> 293 | S20: =R20+P20+N20+L20+J20 -> 844 | T20: 46146 | V20: Instalado | W20: =VLOOKUP(C20,'Status oficina'!$A$2:$C$208,3,FALSE) -> Activa
A21: Centro Occidental | B21: San Diego | C21: 9467 | D21: 9467MFCO01 | E21: Canon iR1025 | F21: DRL39403 | G21: 10.10.158.201 | H21: 126543 | I21: 126738 | J21: =I21-H21 -> 195 | K21: 126927 | L21: =K21-I21 -> 189 | M21: =VLOOKUP(G21,'[1]01-09 al 30-09'!$G:$AI,29,FALSE) -> 127026 | N21: =M21-K21 -> 99 | O21: =VLOOKUP(G21,'[1]01-09 al 30-09'!$G:$AS,39,FALSE) -> 127178 | P21: =O21-M21 -> 152 | S21: =R21+P21+N21+L21+J21 -> 635 | T21: 46146 | V21: Instalado | W21: =VLOOKUP(C21,'Status oficina'!$A$2:$C$208,3,FALSE) -> Activa
A22: Centro Occidental | B22: Lomas Del Este | C22: 9420 | D22: 9420MFTQ01 | E22: Canon iR1025 | F22: DRL39438 | G22: 10.10.100.110 | H22: 221210 | I22: 221210 | J22: =I22-H22 -> 0 | K22: 221210 | L22: =K22-I22 -> 0 | M22: =VLOOKUP(G22,'[1]01-09 al 30-09'!$G:$AI,29,FALSE) -> 221210 | N22: =M22-K22 -> 0 | O22: =VLOOKUP(G22,'[1]01-09 al 30-09'!$G:$AS,39,FALSE) -> 221210 | P22: =O22-M22 -> 0 | S22: =R22+P22+N22+L22+J22 -> 0 | T22: 46146 | V22: Cierre definitivo | W22: =VLOOKUP(C22,'Status oficina'!$A$2:$C$208,3,FALSE) -> Cierre definitivo
A23: Metro II | B23: Concresa | C23: 9231 | D23: 9231MFTQ01 | E23: Canon iR1025 | F23: DRL43466 | G23: 10.14.93.201 | H23: 207435 | I23: 207637 | J23: =I23-H23 -> 202 | K23: 207765 | L23: =K23-I23 -> 128 | M23: =VLOOKUP(G23,'[1]01-09 al 30-09'!$G:$AI,29,FALSE) -> 207936 | N23: =M23-K23 -> 171 | O23: =VLOOKUP(G23,'[1]01-09 al 30-09'!$G:$AS,39,FALSE) -> 208081 | P23: =O23-M23 -> 145 | S23: =R23+P23+N23+L23+J23 -> 646 | T23: 46146 | V23: Instalado | W23: =VLOOKUP(C23,'Status oficina'!$A$2:$C$208,3,FALSE) -> Activa
A24: Centro Occidental | B24: El Recreo | C24: 9425 | D24: 9425MFTQ01 | E24: Canon iR1025 | F24: DRL43476 | G24: 10.10.171.207 | H24: 261899 | I24: 262242 | J24: =I24-H24 -> 343 | K24: 263283 | L24: =K24-I24 -> 1041 | M24: =VLOOKUP(G24,'[1]01-09 al 30-09'!$G:$AI,29,FALSE) -> 263283 | N24: =M24-K24 -> 0 | O24: =VLOOKUP(G24,'[1]01-09 al 30-09'!$G:$AS,39,FALSE) -> 263474 | P24: =O24-M24 -> 191 | S24: =R24+P24+N24+L24+J24 -> 1575 | T24: 46146 | V24: Instalado | W24: =VLOOKUP(C24,'Status oficina'!$A$2:$C$208,3,FALSE) -> Activa
A25: Metro II | B25: Centro Plaza | C25: 9294 | D25: 9294MFGE01 | E25: Canon iR1025 | F25: DRL43547 | G25: 10.14.47.204 | H25: 283273 | I25: 283288 | J25: =I25-H25 -> 15 | K25: 283308 | L25: =K25-I25 -> 20 | M25: =VLOOKUP(G25,'[1]01-09 al 30-09'!$G:$AI,29,FALSE) -> 283349 | N25: =M25-K25 -> 41 | O25: =VLOOKUP(G25,'[1]01-09 al 30-09'!$G:$AS,39,FALSE) -> 283386 | P25: =O25-M25 -> 37 | S25: =R25+P25+N25+L25+J25 -> 113 | T25: 46146 | V25: Instalado | W25: =VLOOKUP(C25,'Status oficina'!$A$2:$C$208,3,FALSE) -> Activa
A26: Metro II | B26: La Trinidad | C26: 9228 | D26: 9228MFAP01 | E26: Canon iR2525 | F26: FRU47935 | G26: 10.14.8.201 | H26: 384856 | I26: 385890 | J26: =I26-H26 -> 1034 | K26: 386818 | L26: =K26-I26 -> 928 | M26: =VLOOKUP(G26,'[1]01-09 al 30-09'!$G:$AI,29,FALSE) -> 387647 | N26: =M26-K26 -> 829 | O26: =VLOOKUP(G26,'[1]01-09 al 30-09'!$G:$AS,39,FALSE) -> 388675 | P26: =O26-M26 -> 1028 | S26: =R26+P26+N26+L26+J26 -> 3819 | T26: 46146 | V26: Instalado | W26: =VLOOKUP(C26,'Status oficina'!$A$2:$C$208,3,FALSE) -> Activa
A27: Metro II | B27: Universidad Metropolitana | C27: 9927 | D27: 9927MFAP01 | E27: Canon iR1025 | F27: DRL43565 | G27: 10.10.184.201 | H27: 188326 | I27: 188557 | J27: =I27-H27 -> 231 | K27: 188674 | L27: =K27-I27 -> 117 | M27: =VLOOKUP(G27,'[1]01-09 al 30-09'!$G:$AI,29,FALSE) -> 188790 | N27: =M27-K27 -> 116 | O27: =VLOOKUP(G27,'[1]01-09 al 30-09'!$G:$AS,39,FALSE) -> 189051 | P27: =O27-M27 -> 261 | S27: =R27+P27+N27+L27+J27 -> 725 | T27: 46146 | V27: Instalado | W27: =VLOOKUP(C27,'Status oficina'!$A$2:$C$208,3,FALSE) -> Activa
A28: Oriente | B28: Lecherias | C28: 9538 | D28: 9538MFAP01 | E28: Canon iR1025 | F28: DRL43579 | G28: 10.10.163.200 | H28: 250936 | I28: 250936 | J28: =I28-H28 -> 0 | K28: 250936 | L28: =K28-I28 -> 0 | M28: =VLOOKUP(G28,'[1]01-09 al 30-09'!$G:$AI,29,FALSE) -> 250936 | N28: =M28-K28 -> 0 | O28: =VLOOKUP(G28,'[1]01-09 al 30-09'!$G:$AS,39,FALSE) -> 250936 | P28: =O28-M28 -> 0 | S28: =R28+P28+N28+L28+J28 -> 0 | T28: 46146 | V28: Cierre temporal | W28: =VLOOKUP(C28,'Status oficina'!$A$2:$C$208,3,FALSE) -> Cierre temporal
A29: Centro Occidental | B29: San Blas | C29: 9430 | D29: 9430MFTQ01 | E29: Canon iR1025 | F29: DRL43583 | G29: 10.11.11.200 | H29: 155750 | I29: 156112 | J29: =I29-H29 -> 362 | K29: 156449 | L29: =K29-I29 -> 337 | M29: =VLOOKUP(G29,'[1]01-09 al 30-09'!$G:$AI,29,FALSE) -> 156715 | N29: =M29-K29 -> 266 | O29: =VLOOKUP(G29,'[1]01-09 al 30-09'!$G:$AS,39,FALSE) -> 157479 | P29: =O29-M29 -> 764 | S29: =R29+P29+N29+L29+J29 -> 1729 | T29: 46146 | V29: Instalado | W29: =VLOOKUP(C29,'Status oficina'!$A$2:$C$208,3,FALSE) -> Activa
A30: Centro Occidental | B30: Barquisimeto | C30: 9833 | D30: 9833MFGE01 | E30: Canon iR1025 | F30: DRL43591 | G30: 10.10.230.200 | H30: 426870 | I30: 426870 | J30: =I30-H30 -> 0 | K30: 426870 | L30: =K30-I30 -> 0 | M30: =VLOOKUP(G30,'[1]01-09 al 30-09'!$G:$AI,29,FALSE) -> 426870 | N30: =M30-K30 -> 0 | O30: =VLOOKUP(G30,'[1]01-09 al 30-09'!$G:$AS,39,FALSE) -> 426870 | P30: =O30-M30 -> 0 | S30: =R30+P30+N30+L30+J30 -> 0 | T30: 46146 | U30: Operativa pero sin impresiones/Se embala la impresora por tener poco uso 10/03/2025 | V30: Pendiente Retiro | W30: =VLOOKUP(C30,'Status oficina'!$A$2:$C$208,3,FALSE) -> Activa
A31: Centro Occidental | B31: Barinas | C31: 9831 | D31: 9831MFEN01 | E31: Canon iR1025 | F31: DRL43598 | G31: 10.11.9.201 | H31: 127880 | I31: 127942 | J31: =I31-H31 -> 62 | K31: 127948 | L31: =K31-I31 -> 6 | M31: =VLOOKUP(G31,'[1]01-09 al 30-09'!$G:$AI,29,FALSE) -> 127989 | N31: =M31-K31 -> 41 | O31: =VLOOKUP(G31,'[1]01-09 al 30-09'!$G:$AS,39,FALSE) -> 128020 | P31: =O31-M31 -> 31 | S31: =R31+P31+N31+L31+J31 -> 140 | T31: 46146 | V31: Instalado | W31: =VLOOKUP(C31,'Status oficina'!$A$2:$C$208,3,FALSE) -> Activa
A32: Metro II | B32: Altamira | C32: 9221 | D32: 9221MFBC01 | E32: Canon iR1025 | F32: DRL43601 | G32: 10.10.141.201 | H32: 136091 | I32: 136091 | J32: =I32-H32 -> 0 | K32: 136091 | L32: =K32-I32 -> 0 | M32: 136091 | N32: =M32-K32 -> 0 | O32: 136091 | P32: =O32-M32 -> 0 | S32: =R32+P32+N32+L32+J32 -> 0 | T32: 46146 | U32: Se desincorpora ya que el personal se retirar de la oficina 28/11/2025/Se procede a trasladar de la agencia chuao y se instala en la agencia altamira 02/12/2025 | V32: Cierre definitivo | W32: =VLOOKUP(C32,'Status oficina'!$A$2:$C$208,3,FALSE) -> Cierre definitivo
A33: Metro I | B33: Multiplazas El Paraiso | C33: 9264 | D33: 9264MFTQ01 | E33: Canon iR1025 | F33: DRL43605 | G33: 10.11.23.201 | H33: 204247 | I33: 204277 | J33: =I33-H33 -> 30 | K33: 204294 | L33: =K33-I33 -> 17 | M33: =VLOOKUP(G33,'[1]01-09 al 30-09'!$G:$AI,29,FALSE) -> 204303 | N33: =M33-K33 -> 9 | O33: =VLOOKUP(G33,'[1]01-09 al 30-09'!$G:$AS,39,FALSE) -> 204321 | P33: =O33-M33 -> 18 | S33: =R33+P33+N33+L33+J33 -> 74 | T33: 46146 | V33: Instalado | W33: =VLOOKUP(C33,'Status oficina'!$A$2:$C$208,3,FALSE) -> Activa
A34: Metro I | B34: La Guaira | C34: 9241 | D34: 9241MFAP01 | E34: Canon iR2525 | F34: FRU40598 | G34: 10.10.145.200 | H34: 497108 | I34: 497108 | J34: =I34-H34 -> 0 | K34: 497108 | L34: =K34-I34 -> 0 | M34: =VLOOKUP(G34,'[1]01-09 al 30-09'!$G:$AI,29,FALSE) -> 497108 | N34: =M34-K34 -> 0 | O34: =VLOOKUP(G34,'[1]01-09 al 30-09'!$G:$AS,39,FALSE) -> 497108 | P34: =O34-M34 -> 0 | S34: =R34+P34+N34+L34+J34 -> 0 | T34: 46146 | V34: Cierre temporal | W34: =VLOOKUP(C34,'Status oficina'!$A$2:$C$208,3,FALSE) -> Cierre temporal
A35: Metro I | B35: La Guaira | C35: 9241 | D35: 9241MFGE01 | E35: Canon iR1025 | F35: DRL54932 | G35: 10.10.145.202 | H35: 85823 | I35: 85823 | J35: =I35-H35 -> 0 | K35: 85823 | L35: =K35-I35 -> 0 | M35: =VLOOKUP(G35,'[1]01-09 al 30-09'!$G:$AI,29,FALSE) -> 85823 | N35: =M35-K35 -> 0 | O35: =VLOOKUP(G35,'[1]01-09 al 30-09'!$G:$AS,39,FALSE) -> 85823 | P35: =O35-M35 -> 0 | S35: =R35+P35+N35+L35+J35 -> 0 | T35: 46146 | V35: Cierre temporal | W35: =VLOOKUP(C35,'Status oficina'!$A$2:$C$208,3,FALSE) -> Cierre temporal
A36: Metro II | B36: CMD La Trinidad | C36: 9940 | D36: 9940MFAP01 | E36: Canon iR1025 | F36: DRL43607 | G36: 10.10.97.200 | H36: 273004 | I36: 273201 | J36: =I36-H36 -> 197 | K36: 273457 | L36: =K36-I36 -> 256 | M36: =VLOOKUP(G36,'[1]01-09 al 30-09'!$G:$AI,29,FALSE) -> 273728 | N36: =M36-K36 -> 271 | O36: =VLOOKUP(G36,'[1]01-09 al 30-09'!$G:$AS,39,FALSE) -> 274222 | P36: =O36-M36 -> 494 | S36: =R36+P36+N36+L36+J36 -> 1218 | T36: 46146 | V36: Instalado | W36: =VLOOKUP(C36,'Status oficina'!$A$2:$C$208,3,FALSE) -> Activa
A37: Occidente | B37: Sambil Paraguana | C37: 9499 | D37: 9499MFTQ01 | E37: Canon iR1025 | F37: DRL45547 | G37: 10.10.240.200 | H37: 97540 | I37: 97602 | J37: =I37-H37 -> 62 | K37: 97644 | L37: =K37-I37 -> 42 | M37: =VLOOKUP(G37,'[1]01-09 al 30-09'!$G:$AI,29,FALSE) -> 97680 | N37: =M37-K37 -> 36 | O37: =VLOOKUP(G37,'[1]01-09 al 30-09'!$G:$AS,39,FALSE) -> 97747 | P37: =O37-M37 -> 67 | S37: =R37+P37+N37+L37+J37 -> 207 | T37: 46146 | V37: Instalado | W37: =VLOOKUP(C37,'Status oficina'!$A$2:$C$208,3,FALSE) -> Activa
A38: Oriente | B38: Guaraguao | C38: 9567 | D38: 9567MFAP01 | E38: Canon iR1025 | F38: DRL45555 | G38: 10.11.83.200 | H38: 206606 | I38: 206729 | J38: =I38-H38 -> 123 | K38: 206818 | L38: =K38-I38 -> 89 | M38: =VLOOKUP(G38,'[1]01-09 al 30-09'!$G:$AI,29,FALSE) -> 206882 | N38: =M38-K38 -> 64 | O38: =VLOOKUP(G38,'[1]01-09 al 30-09'!$G:$AS,39,FALSE) -> 207090 | P38: =O38-M38 -> 208 | S38: =R38+P38+N38+L38+J38 -> 484 | T38: 46146 | V38: Instalado | W38: =VLOOKUP(C38,'Status oficina'!$A$2:$C$208,3,FALSE) -> Activa
A39: Occidente | B39: Coro | C39: 9826 | D39: 9826MFGE01 | E39: Canon iR1025 | F39: DRL45563 | G39: 10.10.146.201 | H39: 199742 | I39: 200083 | J39: =I39-H39 -> 341 | K39: 200357 | L39: =K39-I39 -> 274 | M39: =VLOOKUP(G39,'[1]01-09 al 30-09'!$G:$AI,29,FALSE) -> 200557 | N39: =M39-K39 -> 200 | O39: =VLOOKUP(G39,'[1]01-09 al 30-09'!$G:$AS,39,FALSE) -> 200797 | P39: =O39-M39 -> 240 | S39: =R39+P39+N39+L39+J39 -> 1055 | T39: 46146 | V39: Instalado | W39: =VLOOKUP(C39,'Status oficina'!$A$2:$C$208,3,FALSE) -> Activa
A40: Metro I | B40: La Candelaria | C40: 9252 | D40: 9252MFAP01 | E40: Canon iR2525 | F40: FRU38985 | G40: 10.11.13.201 | H40: 666565 | I40: 666565 | J40: =I40-H40 -> 0 | K40: 666565 | L40: =K40-I40 -> 0 | M40: =VLOOKUP(G40,'[1]01-09 al 30-09'!$G:$AI,29,FALSE) -> 666565 | N40: =M40-K40 -> 0 | O40: =VLOOKUP(G40,'[1]01-09 al 30-09'!$G:$AS,39,FALSE) -> 666565 | P40: =O40-M40 -> 0 | S40: =R40+P40+N40+L40+J40 -> 0 | T40: 46146 | U40: Cierre Definitivo 12/12/2023 | V40: Cierre definitivo | W40: =VLOOKUP(C40,'Status oficina'!$A$2:$C$208,3,FALSE) -> Cierre definitivo
...

Sheet Hoja3
A1: Serial | B1: Serial
A2: DRL37783 | B2: DRL37783 | C2: =IF(A2=B2,TRUE,FALSE) -> TRUE
A3: DRL37786 | B3: DRL37786 | C3: =IF(A3=B3,TRUE,FALSE) -> TRUE
A4: DRL37787 | B4: DRL37787 | C4: =IF(A4=B4,TRUE,FALSE) -> TRUE
A5: DRL37936 | B5: DRL37936 | C5: =IF(A5=B5,TRUE,FALSE) -> TRUE
A6: DRL37941 | B6: DRL37941 | C6: =IF(A6=B6,TRUE,FALSE) -> TRUE
A7: DRL37947 | B7: DRL37947 | C7: =IF(A7=B7,TRUE,FALSE) -> TRUE
A8: DRL37948 | B8: DRL37948 | C8: =IF(A8=B8,TRUE,FALSE) -> TRUE
A9: DRL37949 | B9: DRL37949 | C9: =IF(A9=B9,TRUE,FALSE) -> TRUE
A10: DRL37951 | B10: DRL37951 | C10: =IF(A10=B10,TRUE,FALSE) -> TRUE
A11: DRL37952 | B11: DRL37952 | C11: =IF(A11=B11,TRUE,FALSE) -> TRUE
A12: DRL37991 | B12: DRL37991 | C12: =IF(A12=B12,TRUE,FALSE) -> TRUE
A13: DRL38000 | B13: DRL38000 | C13: =IF(A13=B13,TRUE,FALSE) -> TRUE
... A248: FRU84158 | B248: FRU84161 | C248: =IF(A248=B248,TRUE,FALSE) -> FALSE
A249: FRU84161 | C249: =IF(A249=B249,TRUE,FALSE) -> FALSE

Sheet Status oficina
A1: Codigo de Negocio | B1: Oficina | C1: Status
A2: 9203 | B2: Casa Bera | C2: Cierre definitivo
A3: 9211 | B3: San Francisco | C3: Activa
A4: 9212 | B4: PRADOS DE MARIA | C4: Cierre temporal
A5: 9213 | B5: Sabana Grande | C5: Activa
A6: 9214 | B6: Avenida Francisco Solano | C6: Cierre temporal
A7: 9217 | B7: Principal | C7: Activa
A8: 9218 | B8: Terrazas del Ávila | C8: Activa
A9: 9219 | B9: Caja Interna | C9: Activa
A10: 9221 | B10: Altamira | C10: Cierre definitivo
A11: 9224 | B11: El Rosal | C11: Activa
A12: 9225 | B12: Las Mercedes | C12: Activa
A13: 9226 | B13: Catia La Mar | C13: Activa
... A207: 9964 | B207: D.H.L La California | C207: Cierre definitivo
A208: 0000 | B208: HP | C208: Sede

Sheet Hoja2
A1: 606891
A2: 217461
A3: 363696
A4: 671985
A5: 494977
A6: 480244
A7: 790927
A8: 775542
A9: 301218
A10: 505110
A11: 359973
A12: 215621
... A361: 96469

Sheet Calidad de Prestamo y Retiro
A1: Region | B1: Nombre Oficina | C1: Codigo de Oficina | D1: Nombre de Host Oficina | E1: DisplayName | F1: Serial | G1: IPv4Address | H1: 42643 | I1: 03-10 al 07-10 | J1: Contador 07-10 | K1: 10-10 al 14-10 | L1: Contador 14-10 | M1: 17-10 al 21-10 | N1: Contador 21-10 | O1: 24-10 al 28-10 | P1: Contador 28-10 | Q1: 42674 | R1: Contador 31-10 | S1: Contador Mensual | T1: Observaciones
A2: Metropolitana II | B2: La Vega | C2: 9262 | D2: 9262MFGE01 | E2: Canon iR1025 | F2: DRL43599 | G2: 10.10.116.203 | H2: 80191 | S2: 0 | T2: Esta Agencia fue cerrada, Contador: 80191, Fecha 01-10-2016
A3: Metropolitana III | B3: Petare | C3: 9296 | D3: 9296MFAP01 | E3: Canon iR2525 | F3: FRU47913 | G3: 10.10.20.201 | H3: 118073 | S3: 0 | T3: Esta Agencia fue cerrada, Contador: 118073, Fecha 01-10-2016
A4: Metropolitana III | B4: Petare | C4: 9296 | D4: 9296MFTQ01 | E4: Canon iR1025 | F4: DRL51798 | G4: 10.10.20.200 | H4: 9877 | S4: 0 | T4: Esta Agencia fue cerrada, Contador: 9877, Fecha 01-10-2016
A5: Sur | B5: Unare - Pto. Ordaz | C5: 9611 | D5: 9611MFGE01 | E5: Canon iR1025 | F5: DRL45565 | G5: 10.10.56.200 | H5: 186655 | S5: 0 | T5: Impresora Desconectada, Pendiente por Retirar, Contador 186660
A6: Metropolitana III | B6: Valle Arriba Market | C6: 9439 | D6: 9439MFAP01 | E6: Canon iR1025 | F6: DRL54297 | G6: 10.14.95.200 | H6: 95705 | S6: 0 | T6: Esta Agencia fue cerrada, Contador: 95910, Fecha 03-10-2016
A7: Metropolitana I | B7: Galerias Avila | C7: 9942 | D7: 9942MFRS01 | E7: Canon iR2525 | F7: FRU38037 | G7: 10.10.27.200 | H7: 91075 | S7: 0 | T7: Esta Agencia fue cerrada, Contador: 91144, Fecha 01-10-2016
A8: Metropolitana III | B8: Galerias Los Naranjos | C8: 9945 | D8: 9945MFAP01 | E8: Canon iR1025 | F8: DRL54812 | G8: 10.10.26.200 | H8: 142199 | S8: 0 | T8: Esta Agencia fue cerrada, Contador: 142393, Fecha 04-10-2016
A9: Metropolitana I | B9: Parque Central | C9: 9215 | D9: 9215MFAP01 | E9: Canon iR2525 | F9: FRU38957 | G9: 10.10.149.210 | H9: 200634 | S9: 0 | T9: Esta Agencia fue cerrada, Contador: 200773, Fecha 04-10-2016
A10: Metropolitana I | B10: Parque Central | C10: 9215 | D10: 9215MFTQ01 | E10: Canon iR1025 | F10: DRL37943 | G10: 10.10.149.201 | H10: 55835 | I10: 56228 | J10: 393 | K10: 56319 | L10: 91 | S10: 484 | T10: Esta Agencia fue cerrada, Contador: 56319, Fecha 04-10-2016
A11: Metropolitana II | B11: La Pilita | C11: 9251 | D11: 9251MFAP01 | E11: Canon iR2525 | F11: FRU46125 | G11: 10.10.239.200 | H11: 210023 | I11: 210315 | J11: 292 | S11: 292 | T11: Esta Agencia fue cerrada, Contador: 210315, Fecha 08-10-2016
A12: Metropolitana II | B12: La Pilita | C12: 9251 | D12: 9251MFTQ01 | E12: Canon iR1025 | F12: DRL54962 | G12: 10.10.239.201 | H12: 40509 | I12: 40722 | J12: 213 | S12: 213 | T12: Esta Agencia fue cerrada, Contador: 40722, Fecha 08-10-2016
A13: Metropolitana I | B13: Las Acacias | C13: 9254 | D13: 9254MFBV01 | E13: Canon iR1025 | F13: DRL37786 | G13: 10.10.255.200 | H13: 34540 | I13: 34722 | J13: 182 | S13: 182 | T13: Esta Agencia fue cerrada, Contador: 34722, Fecha 08-10-2016
A14: Metropolitana III | B14: Los Samanes | C14: 9364 | D14: 9364MFAP01 | E14: Canon iR2525 | F14: FRU47855 | G14: 10.14.50.207 | H14: 170520 | I14: 171131 | J14: 611 | S14: 611 | T14: Esta Agencia fue cerrada, Contador: 171131, Fecha 08-10-2016
A15: Metropolitana I | B15: El Bosque | C15: 9223 | D15: 9223MFAP01 | E15: Canon iR2525 | F15: FRU38986 | G15: 10.10.22.203 | H15: 393975 | I15: 394738 | J15: 763 | K15: 394746 | L15: 8 | S15: 771 | T15: Esta Agencia fue cerrada, Contador: 394746, Fecha 10-10-2016
A16: Metropolitana I | B16: El Bosque | C16: 9223 | D16: 9223MFNE01 | E16: Canon iR1025 | F16: DRL37773 | G16: 10.10.22.202 | H16: 81499 | I16: 81651 | J16: 152 | S16: 152 | T16: Esta Agencia fue cerrada, Contador: 81651, Fecha 10-10-2016
A17: Metropolitana I | B17: Sambil | C17: 9237 | D17: 9237MFGE01 | E17: Canon iR1025 | F17: DRL38010 | G17: 10.10.45.200 | H17: 86575 | I17: 86751 | J17: 176 | K17: 86973 | L17: 222 | S17: 398 | T17: Esta Agencia fue cerrada, Contador: 86976, Fecha 11-10-2016
A18: Metropolitana III | B18: I.B.M | C18: 9938 | D18: 9938MFAP01 | E18: Canon iR1025 | F18: DRL45556 | G18: 10.10.29.201 | H18: 35366 | I18: 35471 | J18: 105 | K18: 35686 | L18: 215 | S18: 320 | T18: Esta Agencia fue cerrada, Contador: 35686, Fecha 14-10-2016
A19: Metropolitana II | B19: El Paraiso II | C19: 9347 | D19: 9347MFAP01 | E19: Canon iR2525 | F19: FRU48558 | G19: 10.14.67.201 | H19: 49324 | I19: 49583 | J19: 259 | K19: 49792 | L19: 209 | S19: 468 | T19: Esta Agencia fue cerrada, Contador: 49792, Fecha 15-10-2016
A20: Metropolitana II | B20: El Paraiso II | C20: 9347 | D20: 9347MFGE01 | E20: Canon iR1025 | F20: DRL54052 | G20: 10.14.67.202 | H20: 167652 | I20: 168254 | J20: 602 | K20: 168527 | L20: 273 | S20: 875 | T20: Esta Agencia fue cerrada, Contador: 168527, Fecha 15-10-2016
A21: Metropolitana II | B21: Esquina Salas | C21: 9949 | D21: 9949MFAP01 | E21: Canon iR2525 | F21: FRU46135 | G21: 10.10.54.201 | H21: 181637 | I21: 182083 | J21: 446 | K21: 182698 | L21: 615 | S21: 1061 | T21: Esta Agencia fue cerrada, Contador: 182698, Fecha 15-10-2016
A22: Metropolitana II | B22: Esquina Salas | C22: 9949 | D22: 9949MFGE01 | E22: Canon iR1025 | F22: DRL51918 | G22: 10.10.54.200 | H22: 57385 | I22: 57485 | J22: 100 | K22: 57631 | L22: 146 | S22: 246 | T22: Esta Agencia fue cerrada, Contador: 57631, Fecha 15-10-2016
A23: Metropolitana III | B23: Boleita Center | C23: 9944 | D23: 9944MFAP01 | E23: Canon iR2525 | F23: FRU46147 | G23: 10.10.38.200 | H23: 120120 | I23: 120498 | J23: 378 | K23: 121072 | L23: 574 | S23: 952 | T23: Esta Agencia fue cerrada, Contador: 121072, Fecha 15-10-2016
A24: Metropolitana III | B24: El Marques II | C24: 9372 | D24: 9372MFAP01 | E24: Canon iR2525 | F24: FRU46103 | G24: 10.14.62.201 | H24: 234808 | I24: 235413 | J24: 605 | K24: 236207 | L24: 794 | S24: 1399 | T24: Esta Agencia fue cerrada, Contador: 236207, Fecha 17-10-2016
A25: Metropolitana III | B25: El Marques II | C25: 9372 | D25: 9372MFGE01 | E25: Canon iR1025 | F25: DRL52655 | G25: 10.14.62.200 | H25: 38300 | I25: 38407 | J25: 107 | K25: 38487 | L25: 80 | S25: 187 | T25: Esta Agencia fue cerrada, Contador: 38487, Fecha 17-10-2016
A26: Metropolitana II | B26: Mercado San Jorge | C26: 9946 | D26: 9946MFGE01 | E26: Canon iR1025 | F26: DRL52644 | G26: 10.10.134.200 | H26: 75361 | I26: 75572 | J26: 211 | K26: 75862 | L26: 290 | S26: 501 | T26: Esta Agencia fue cerrada, Contador: 75862, Fecha 17-10-2016
A27: Metropolitana I | B27: El Bosque | C27: 9223 | D27: 9223MFTQ01 | E27: Canon iR1025 | F27: DRL37782 | G27: 10.10.22.201 | H27: 90437 | I27: 90969 | J27: 532 | K27: 91364 | L27: 395 | M27: 91527 | N27: 163 | S27: 1090 | T27: Esta Agencia fue cerrada, Contador: 91527, Fecha 21-10-2016
A28: Oriente | B28: Gold Country | C28: 9537 | D28: 9537MFAP01 | E28: Canon iR2525 | F28: FRU83003 | G28: 10.10.47.200 | H28: 149695 | I28: 150101 | J28: 406 | K28: 150425 | L28: 324 | M28: 150960 | N28: 535 | S28: 1265 | T28: Esta Agencia fue cerrada, Contador: 150960, Fecha 22-10-2016
A29: Oriente | B29: Gold Country | C29: 9537 | D29: 9537MFTQ01 | E29: Canon iR1025 | F29: DRL64121 | G29: 10.10.47.201 | H29: 52146 | I29: 52274 | J29: 128 | K29: 52418 | L29: 144 | M29: 52613 | N29: 195 | S29: 467 | T29: Esta Agencia fue cerrada, Contador: 52613, Fecha 22-10-2016 ( La impresora fue reemplazada con el S/N: DRL55642 de Agencia Barcelona, Autorizado por Logistica y Soporte en Sitio)
A30: Oriente | B30: Barcelona | C30: 9560 | D30: 9560MFEN01 | E30: Canon iR1025 | F30: DRL55642 | G30: 10.10.90.203 | H30: 146188 | I30: 146636 | J30: 448 | K30: 147072 | L30: 436 | M30: 147653 | N30: 581 | S30: 1465 | T30: La impresora fue reemplazada con el S/N: DRL64121, Autorizado por Logistica y Soporte en Sitio
A31: Carabobo | B31: Guacara | C31: 9424 | D31: 9424MFAP01 | E31: Canon iR2525 | F31: FRU38980 | G31: 10.10.236.200 | H31: 421868 | I31: 423421 | J31: 1553 | K31: 424550 | L31: 1129 | M31: 426552 | N31: 2002 | S31: 4684 | T31: Esta Agencia fue cerrada, Contador: 426522, Fecha 22-10-2016
A32: Carabobo | B32: Guacara | C32: 9424 | D32: 9424MFGE01 | E32: Canon iR1025 | F32: DRL39407 | G32: 10.10.236.201 | H32: 141558 | I32: 141970 | J32: 412 | K32: 143186 | L32: 1216 | M32: 144210 | N32: 1024 | S32: 2652 | T32: Esta Agencia fue cerrada, Contador: 144210, Fecha 22-10-2016
A33: Occidente | B33: Las Playitas | C33: 9812 | D33: 9812MFAP01 | E33: Canon iR2525 | F33: FRU48554 | G33: 10.10.2.201 | H33: 187274 | I33: 188215 | J33: 941 | K33: 189269 | L33: 1054 | M33: 190105 | N33: 836 | S33: 2831 | T33: Esta Agencia fue cerrada, Contador: 190105, Fecha 22-10-2016
A34: Occidente | B34: Las Playitas | C34: 9812 | D34: 9812MFAP01 | E34: Canon iR1025 | F34: DRL45534 | G34: 10.10.2.200 | H34: 76386 | I34: 76839 | J34: 453 | K34: 77028 | L34: 189 | M34: 77320 | N34: 292 | S34: 934 | T34: Esta Agencia fue cerrada, Contador: 77320, Fecha 22-10-2016
A35: Andina | B35: La castellana Mérida | C35: 9958 | D35: 9958MFAP01 | E35: Canon iR2525 | F35: FRU40601 | G35: 10.10.61.200 | H35: 246962 | I35: 247562 | J35: 600 | K35: 248041 | L35: 479 | M35: 248320 | N35: 279 | S35: 1358 | T35: Esta Agencia fue cerrada, Contador: 248320, Fecha 22-10-2016
A36: Andina | B36: La castellana Mérida | C36: 9958 | D36: 9958MFTQ01 | E36: Canon iR1025 | F36: DRL39201 | G36: 10.10.61.201 | H36: 75477 | I36: 75553 | J36: 76 | K36: 75630 | L36: 77 | M36: 75718 | N36: 88 | S36: 241 | T36: Esta Agencia fue cerrada, Contador: 75718, Fecha 22-10-2016
A37: Centro | B37: La Coromoto - Maracay | C37: 9380 | D37: 9380MFAP01 | E37: Canon iR2525 | F37: FRU46152 | G37: 10.11.14.201 | H37: 262103 | I37: 262570 | J37: 467 | K37: 263029 | L37: 459 | M37: 263922 | N37: 893 | S37: 1819 | T37: Esta Agencia fue cerrada, Contador: 263922, Fecha 24-10-2016
A38: Centro | B38: La Coromoto - Maracay | C38: 9380 | D38: 9380MFGE01 | E38: Canon iR1025 | F38: DRL52648 | G38: 10.11.14.200 | H38: 124645 | I38: 124730 | J38: 85 | K38: 125194 | L38: 464 | M38: 125573 | N38: 379 | S38: 928 | T38: Esta Agencia fue cerrada, Contador: 125573, Fecha 24-10-2016
A39: Occidente | B39: Enelco | C39: 9882 | D39: 9882MFAP01 | E39: Canon iR1025 | F39: DRL49249 | G39: 10.14.55.200 | H39: 22526 | I39: 22526 | J39: 0 | S39: 0 | T39: Esta Agencia fue cerrada, Contador: 22526, Fecha 28-10-2016
A40: Region | B40: Nombre Oficina | C40: Codigo de Oficina | D40: Nombre de Host Oficina | E40: DisplayName | F40: Serial | G40: IPv4Address | H40: 42674 | I40: 01-11 al 04-11 | J40: Contador 04-11 | K40: 07-11 al 11-11 | L40: Contador 11-11 | M40: 14-11 al 18-11 | N40: Contador 18-11 | O40: 21-11 al 25-11 | P40: Contador 25-11 | Q40: 28-11 al 30-11 | R40: Contador 30-11 | S40: Contador Mensual | T40: Observaciones
...

Sheet Hoja1
D4: Region | E4: Nombre Oficina
D5: Carabobo | E5: El Palito
D6: Centro | E6: El Palmar
D7: Occidente | E7: Zona Industrial - Maracaibo
D8: Occidente | E8: Zona Industrial - Maracaibo
D9: Occidente | E9: Bachaquero
D11: Region | E11: Nombre Oficina | F11: Modelo de Equipo
D12: Carabobo | E12: El Palito | F12: IR1025
D13: Occidente | E13: Bachaquero | F13: IR2525
D14: Occidente | E14: Plaza Alonso De Ojeda | F14: IR1025
D15: Occidente | E15: Plaza Alonso De Ojeda | F15: IR2525
D16: Occidente | E16: Zona Industrial - Maracaibo | F16: IR1025
D17: Occidente | E17: Zona Industrial - Maracaibo | F17: IR2525
D18: Occidente | E18: Zona Industrial II - Maracaibo | F18: IR1025
D19: Occidente | E19: Zona Industrial II - Maracaibo | F19: IR2525

Sheet Eliminadas 2021-2022
B1: Agencias
A2: Oriente | B2: El Tigrito | C2: 9681 | D2: 9681MFAP01 | E2: Canon iR2525 | F2: FRU82405 | G2: 10.10.93.202 | I2: Oficina cerrada temporalmente 10-10-2019
A3: Metropolitana II | B3: Filas De Mariche | C3: 9288 | D3: 9288MFAP01 | E3: Canon iR2525 | F3: FRU47921 | G3: 10.10.241.200 | I3: Oficina cerrada temporalmente 12-08-2019 S/N FRU47921 Contador: 247975
A4: Centro Occidente | B4: Metropolis Barquisimeto | C4: 9442 | D4: 9442MFAP01 | E4: Canon iR2525 | F4: FRU47909 | G4: 10.10.152.201 | I4: Cierre de la agencia definitivamente 11/12/2019
A5: Centro Occidente | B5: Barquisimeto - Este | C5: 9839 | D5: 9839MFAP01 | E5: Canon iR2525 | F5: FRU46152 | G5: 10.10.2.201 | I5: Se cambio IP el 09-11-2017 por autorizacion del Banco/Agencia cerrada definitivamente 05/12/2019
A6: Occidente | B6: La Cañada | C6: 9883 | D6: 9883MFAP01 | E6: Canon iR2525 | F6: FRU46128 | G6: 10.14.15.200 | I6: Cierre definitivo de la agencia 09/12/2019
A7: Centro Occidental | B7: Centro Cientifico Metropolitano del Norte | C7: 9481 | D7: 9481MFAP01 | E7: Canon iR2525 | F7: FRU39277 | G7: 10.10.19.201 | I7: Oficina cerrada el día 18-06-2019
A8: Metropolitana I | B8: Centro Sambil II | C8: 9924 | D8: 9924MFAP01 | E8: Canon iR2525 | F8: FRU38015 | G8: 10.14.5.201 | I8: Se desincorpora la impresora por el cierre de la agencia 14/01/2022
A9: Metropolitana I | B9: La Florida | C9: 9222 | D9: 9222MFEN01 | E9: Canon iR2525 | F9: FRU37964 | G9: 10.10.253.201 | I9: Oficina cerrada temporalmente 22-10-2019
A10: Oriente | B10: El Tigrito | C10: 9681 | D10: 9681MFGE01 | E10: Canon iR1025 | F10: DRL64112 | G10: 10.10.93.200 | I10: Oficina cerrada temporalmente 10-10-2019
A11: Oriente | B11: Corp. Emp. Mitsubishi | C11: 9583 | D11: 9583MFAP01 | E11: Canon iR1025 | F11: DRL64106 | G11: 10.10.151.201 | I11: Equipo no ha reportado impresiones/Oficina cerrada temporalmente 15-10-2019
A12: Oriente | B12: Corp. El Morichal / Maturin | C12: 9651 | D12: 9651MFAP01 | E12: Canon iR1025 | F12: DRL61554 | G12: 10.10.228.200 | I12: Oficina cerrada temporalmente
A13: Metropolitana I | B13: Principal | C13: 9217 | D13: 9217MFAP02 | E13: Canon iR1025 | F13: DRL54336 | G13: 10.0.40.207 | I13: Equipo instalado en foyer del auditorio en calidad de prestamo para atencion al cliente (CONT. 227.847) 30-06-2020/Se cambio la ip de la 10.0.40.205 a la 10.0.40.207 06/08/202/Se desincorpora y se embala la impresora y se encuentra en el piso 11 en resguardo 30/11/2021/Se instala en el piso 11 area de logistica y soporte en sitio con autorizacion 16/12/2021 ya que la DRL37939 PRESENTABA FALLAS CON EL ADF/Equipo se encuentra en resguardo en el nivel 3 ya que no fue necesario instalarla en el piso 11
A14: Metropolitana II | B14: San Francisco (H) | C14: 9211 | D14: 9211MFAP02 | E14: Canon iR1025 | F14: DRL54055 | G14: 10.11.29.201 | I14: Equipo Desincorporado y Embalado DRL54055 Contador: 305698 Fecha: 29/05/2019 Pendiente por retirar/Equipo con fallas del Drum y Fusor desde el 17/09/2018/Impresora ya se encuentra en la torre 19/05/2022
A15: Occidente | B15: Las Virtudes | C15: 9860 | D15: 9860MFAP01 | E15: Canon iR1025 | F15: DRL52041 | G15: 10.10.62.200 | I15: Agencia cerrada Definitivamente 06/03/2020
A16: Metropolitana III | B16: Makro - La Urbina | C16: 9275 | D16: 9275MFAP01 | E16: Canon iR1025 | F16: DRL51891 | G16: 10.11.41.203 | I16: Esta impresora fue reemplazada por el equipo DRL51891 en sustitución del DRL54336 por fallas en el mecanismo de impresión, autorizado por la mesa de servicio cambio realizado el 24/10/2018/Impresora desincorporada y embalada por el cierre de la agencia 07/12/2021
A17: Centro Occidental | B17: El Palito | C17: 9473 | D17: 9473MFAP01 | E17: Canon iR1025 | F17: DRL45542 | G17: 10.11.4.11 | I17: Oficina cerrada temporalmente 25-06-2019
A18: Centro Occidental | B18: Sambil Valencia | C18: 9461 | D18: 9461MFTQ01 | E18: Canon iR1025 | F18: DRL45434 | G18: 10.10.150.202 | I18: Se procede al embalaje de esta impresora por autorizacion de logistica y Soporte en sitio el dia 09-10-2019
A19: Centro Occidente | B19: Cabudare | C19: 9859 | D19: 9859MFGE01 | E19: Canon iR1025 | F19: DRL43608 | G19: 10.10.159.201 | I19: Equipo con falla de Drum/Equipo desincorporada ya que presentaba multiples fallas por autorizacion de logistica y soporte en sitio 07/01/2020
A20: Centro | B20: Makro Maracay | C20: 9381 | D20: 9381MFAP01 | E20: Canon iR1025 | F20: DRL43574 | G20: 10.10.111.200 | I20: Desincorporada y embalada 14/12/2021
A21: Carabobo | B21: Firestone | C21: 9479 | D21: 9479MFAP01 | E21: Canon iR1025 | F21: DRL39437 | G21: 10.10.114.200 | I21: Falla de Comunicación desde el 21-05-2018/Agencia cerrada Definitivamente 06/12/2019
A22: Metropolitana I | B22: La Florida | C22: 9222 | D22: 9222MFTQ01 | E22: Canon iR1025 | F22: DRL37942 | G22: 10.10.253.203 | I22: Oficina cerrada temporalmente 22-10-2019
... A26: Oriente | B26: San Felix | C26: 9650 | D26: 9650MFAP01 | E26: Canon iR2525 | F26: FRU83458 | G26: 10.11.26.200 | I26: Equipo embalado por autorización de Logística y soporte en sitio cont. 502076 07/10/2021. Equipo con fallas/Equipo se encuentra en torre en nivel 3
A27: Metropolitana II | B27: Plaza Las Americas | C27: 9289 | D27: 9289MFTQ01 | E27: Canon iR1025 | F27: DRL54906 | I27: Activa sin impresiones/Se desincorpora la impresora ya que tiene la puerta de bandeja manual partida y la base de la puerta partida el dia 26/09/2022 y se encuentra en la torre
A28: Metropolitana II | B28: Clinica Santa Sofia | C28: 9395 | D28: 9395MFCO01 | E28: Canon iR1025 | F28: DRL45545 | G28: 10.11.101.201 | I28: Oficina cerrada temporalmente/Impresora se encuentra en la torre nivel 3 el dia 06/10/2022
A29: Metropolitana II | B29: Campo Alegre | C29: 9970 | D29: 9970MFCO01 | E29: Canon iR1025 | F29: DRL37946 | G29: 10.14.80.201 | I29: Equipo con Falla de DrumSe reemplazo Drum 06/04/2022/Cierre temporalmente de la agencia 16/06/2022/Impresora ya se encuentra en la torre nivel 3
A30: Metropolitana II | B30: Campo Alegre | C30: 9970 | D30: 9970MFAP01 | E30: Canon iR2525 | F30: FRU38050 | G30: 10.14.80.200 | I30: Cierre temporalmente de la agencia 16/06/2022/Impresora ya se encuentra en la torre nivel 3
A31: Metropolitana II | B31: Las Mercedes | C31: 9225 | D31: 9225MFCO01 | E31: Canon iR1025 | F31: DRL52038 | G31: 10.10.243.207 | I31: Impresora se encuentra en la torre nivel 3
A32: Centro Occidental | B32: Villa de Cura | C32: 9390 | D32: 9390MFGE01 | E32: Canon iR1025 | F32: DRL43558 | G32: 10.10.128.230 | I32: Oficina cerrada temporalmente
A33: Centro Occidental | B33: Villa de Cura | C33: 9390 | D33: 9390MFAP01 | E33: Canon iR2525 | F33: FRU46113 | G33: 10.10.128.200 | I33: Oficina cerrada temporalmente
A34: Metropolitana I | B34: San Bernardino | C34: 9216 | D34: 9216MFCO01 | E34: Canon iR1025 | F34: DRL37789 | G34: 10.10.24.200 | I34: Oficina Cerrada
A35: Metropolitana I | B35: San Bernardino | C35: 9216 | D35: 9216MFAP01 | E35: Canon iR2525 | F35: FRU38049 | G35: 10.10.24.201 | I35: Oficina Cerrada
A36: Metropolitana II | B36: Chuao | C36: 9271 | D36: 9271MFBP02 | E36: Canon iR1025 | F36: DRL43584 | I36: Se desincorpora esta impresora y se reemplaza en la agencia por la Canon IR1025 DRL43584 por presenta la base y soporte de la puerta lateral partidos 14/03/2023 y se encuentra en la torre piso 11
A37: Oriente | B37: Puerto Ordaz Oficina | C37: 9510 | D37: 9510MFNE01 | E37: Canon iR1025 | F37: DRL43810 | G37: 10.10.161.200 | I37: Equipo con falla de Drum/Equipo embalado el dia 01/04
A38: Metropolitana II | B38: Buenaventura | C38: 9908 | D38: 9908MFTQ01 | E38: Canon iR1025 | F38: DRL45558 | G38: 10.10.44.201 | I38: Se desincorpora por presentar varias fallas y se encuentra en la torre 04/04/2023
A39: Centro Occidental | B39: Turen | C39: 9858 | D39: 9858MFGE01 | E39: Canon iR1025 | F39: DRL54000 | G39: 10.10.16.200 | I39: Se llamo a la agencia pero no hubo comunicación para validar por que se encuentra sin impresiones/Se desincorpora y se embala la impresora por presentar fallas con autorizacion de logistica y soporte en sitio el dia 11/03/2022/La Impresora se encuentra en el nivel 3 20/04/2023
A41: Occidente | B41: Punto Fijo | C41: 9817 | D41: 9817MFGE01 | E41: Canon iR1025 | F41: DRL55629 | G41: 10.10.147.201 | I41: Equipo embalado por autorización de Logística y soporte en sitio cont. 116456 11/07/2019/Impresora se encuentra en la torre nivel 3 04/05/2023/Impresora se encuentra en la torre nivel 3
A42: Centro Occidental | B42: Puerto Cabello | C42: 9470 | D42: 9470MFGE01 | E42: Canon iR1025 | F42: DRL43595 | G42: 10.10.222.201 | I42: Impresora con fallas de Drum/Se desincorpora y se embala la impresora por presentar fallas con autorizacion 28/03/2023/Impresora se encuentra en la torre nivel 3
A43: Occidente | B43: Sambil Maracaibo | C43: 9878 | D43: 9878MFGE01 | E43: Canon iR1025 | F43: DRL43562 | G43: 10.14.84.201 | I43: Impresora con fallas de Drum/Se desincorpora y se embala la impresora con autorizacion de logistica y soporte en sitio 03/04/2023/Impresora se encuentra en la torre nivel 3 16/05/2023
A44: Occidente | B44: Plaza Republica | C44: 9813 | D44: 9813MFSE01 | E44: Canon iR1025 | F44: DRL49252 | I44: Se desincorpora la impresora por presentar partes dañadas y se instala la DRL45567 EL DIA 28/09/2022/Impresora se encuentra en la torre nivel 3 16/05/2023
...
